<?xml version="1.0" ?>
<robot name="robot_xacro" xmlns:xacro="https://www.ros.org/wiki/xacro">
   
 <!-- Define macros --> 
 <xacro:include filename="$(find exprob_assignment2)/urdf/materials.xacro" />
 <xacro:include filename="$(find exprob_assignment2)/urdf/robot.gazebo" />
 
 <xacro:property name="length_wheel" value="0.04" />
 <xacro:property name="radius_wheel" value="0.1" />

 <xacro:macro name="cylinder_inertia" params="mass r l"> 
 	<inertia ixx="${mass*(3*r*r+l*l)/12}" ixy = "0" ixz = "0"
                 iyy="${mass*(3*r*r+l*l)/12}" iyz = "0" izz="${mass*(r*r)/2}" /> 
 </xacro:macro>
 
 <xacro:macro name="wheel_geometry">
	<geometry>
        <cylinder length="${length_wheel}" radius="${radius_wheel}"/>
     	</geometry>
 </xacro:macro>
 
 <!-- base link -->
 <link name="link_chassis">
    <!-- pose and inertial -->
    <pose>0 0 0.1 0 0 0</pose>
    <inertial>
      <mass value="5"/>
      <origin rpy="0 0 0" xyz="0 0 0.1"/>
      <inertia ixx="0.0395416666667" ixy="0" ixz="0" iyy="0.106208333333" iyz="0" izz="0.106208333333"/>
    </inertial> 
    <collision name="collision_chassis">
      <geometry>
        <box size="0.5 0.3 0.07"/>
      </geometry>
    </collision>
    <visual>
      <origin rpy="0 0 0" xyz="0 0 0"/>
      <geometry>
        <box size="0.5 0.3 0.07"/>
      </geometry>
      <material name="blue"/>
    </visual>
  </link>
    
 <!-- Wheel's macros --> 
 <xacro:macro name="link_wheel" params="name">
	<link name="${name}">
          <inertial>
              <mass value="0.2"/>
              <origin rpy="0 1.5707 1.5707" xyz="0 0 0"/>
              <xacro:cylinder_inertia mass="0.2" r="0.1" l="0.04" />
          </inertial>
          <collision name="${name}_collision">
              <origin rpy="0 1.5707 1.5707" xyz="0 0 0"/>
              <xacro:wheel_geometry />
          </collision>
            <visual name="${name}_visual">
              <origin rpy="0 1.5707 1.5707" xyz="0 0 0"/>
              <xacro:wheel_geometry />
              <material name="orange"/>
            </visual>
        </link>
 </xacro:macro>
 
 <xacro:macro name="joint_wheel" params="name child origin_xyz">
      <joint name="${name}" type="continuous">
        <origin rpy="0 0 0" xyz="${origin_xyz}"/>
        <child link="${child}"/>
        <parent link="link_chassis"/>
        <axis rpy="0 0 0" xyz="0 1 0"/>
        <limit effort="10000" velocity="1000"/>
        <joint_properties damping="1.0" friction="1.0"/>
      </joint>
 </xacro:macro>
 
    <!-- caster front 
    <collision name="caster_front_collision">
      <origin rpy=" 0 0 0" xyz="0.35 0 -0.05"/>
      <geometry>
        <sphere radius="0.05"/>
      </geometry>
      <surface>
        <friction>
          <ode>
            <mu>0</mu>
            <mu2>0</mu2>
            <slip1>1.0</slip1>
            <slip2>1.0</slip2>
          </ode>
        </friction>
      </surface>
    </collision>
    <visual name="caster_front_visual">
      <origin rpy=" 0 0 0" xyz="0.2 0 -0.05"/>
      <geometry>
        <sphere radius="0.05"/>
      </geometry>
    </visual>
    </link> -->
  
  <!-- Create wheels -->  

  <xacro:link_wheel name="link_front_right_wheel" />
  <xacro:link_wheel name="link_front_left_wheel" />
  <xacro:link_wheel name="link_back_right_wheel" />
  <xacro:link_wheel name="link_back_left_wheel" />
  
  <!-- Create wheels' joints --> 
   
  <xacro:joint_wheel name="joint_front_right_wheel"  child="link_front_right_wheel"  origin_xyz="0.2 0.15 0"  />
  <xacro:joint_wheel name="joint_front_left_wheel"   child="link_front_left_wheel"   origin_xyz="0.2 -0.15 0"  />
  <xacro:joint_wheel name="joint_back_right_wheel"  child="link_back_right_wheel"  origin_xyz="-0.2 0.15 0"  />
  <xacro:joint_wheel name="joint_back_left_wheel"   child="link_back_left_wheel"   origin_xyz="-0.2 -0.15 0"  />

  <!-- Arm definition -->

  <link name="arm_base_link">
     <inertial>
        <mass value="0.1"/>
        <origin xyz="0 0 0.025" rpy="0 0 0" />
  	<inertia ixx="0.0000416666667" ixy="0" ixz="0" iyy="0.0000416666667" iyz="0" izz="0.0000416666667"/>
     </inertial>
     <collision>
  	<origin xyz="0 0 0.025" rpy="0 0 0"/>
        <geometry>
        <box size="0.1 0.1 0.05"/>
        </geometry>
     </collision>
     <visual>
        <origin xyz="0 0 0.025" rpy="0 0 0"/>
        <geometry>
        <box size="0.1 0.1 0.05"/>
        </geometry>
        <material name="red" />
     </visual>
  </link>

  <link name="arm_link1">
     <inertial>
        <mass value="0.025"/>
  	<origin xyz="0 0 0.25" rpy="0 0 0" />
  	<inertia ixx="0.000010279" ixy="0" ixz="0" iyy="0.000010279" iyz="0" izz="0.000007225"/>
     </inertial>
     <collision>
        <origin xyz="0 0 0.25" rpy="0 0 0"/>
        <geometry>
        <box size="0.05 0.05 0.5"/>
        </geometry>
     </collision>
     <visual>
        <origin xyz="0 0 0.25" rpy="0 0 0"/>
        <geometry>
        <box size="0.05 0.05 0.5"/>
        </geometry>
        <material name="red" />
     </visual>
  </link>
  
  <link name="arm_link2">
     <inertial>
        <mass value="0.025"/>
  	<origin xyz="0 0 0.25" rpy="0 0 0" />
  	<inertia ixx="0.000010279" ixy="0" ixz="0" iyy="0.000010279" iyz="0" izz="0.000007225"/>
     </inertial>
     <collision>
        <origin xyz="0 0 0.25" rpy="0 0 0"/>
        <geometry>
        <box size="0.05 0.05 0.5"/>
        </geometry>
     </collision>
     <visual>
        <origin xyz="0 0 0.25" rpy="0 0 0"/>
        <geometry>
        <box size="0.05 0.05 0.5"/>
        </geometry>
        <material name="red" />
     </visual>
  </link>
  
  <!-- Arm's joint definition -->
  
  <joint name="arm_base_joint" type="continuous">
  	<axis rpy="0 0 0" xyz="0 0 1"/>
  	<origin rpy="0 0 0" xyz="0 0 0.035"/>
  	<parent link="link_chassis"/>
  	<child link="arm_base_link"/>
  	<limit effort="10000" velocity="1000"/>
        <joint_properties damping="1.0" friction="1.0"/>
  </joint>
  
  <joint name="arm_joint1" type="revolute">
  	<axis rpy="0 0 0" xyz="0 1 0"/>
  	<origin rpy="0 0 0" xyz="0 0 0.05"/>
  	<parent link="arm_base_link"/>
  	<child link="arm_link1"/>
  	<limit effort="1000.0" lower="-1.8" upper="1.8" velocity="0.3"/>
  	<joint_properties damping="1.0" friction="1.0"/>
  </joint>
  
  <joint name="arm_joint2" type="revolute">
  	<axis rpy="0 0 0" xyz="0 1 0"/>
  	<origin rpy="0 0 0" xyz="0 0.05 0.45"/>
  	<parent link="arm_link1"/>
  	<child link="arm_link2"/>
  	<limit effort="1000.0" lower="-1.8" upper="1.8" velocity="0.3"/>
  	<joint_properties damping="1.0" friction="1.0"/>
  </joint>
  
  <!-- Sensors definition -->
  
  <link name="hokuyo_link">
     <collision>
        <origin xyz="0 0 0" rpy="0 0 0"/>
	<geometry>
	<box size="0.05 0.05 0.05"/>
	</geometry>
     </collision>
     <visual>
        <origin xyz="0 0 0" rpy="0 0 0"/>
	<geometry>
        <box size="0.05 0.05 0.05"/>
	</geometry>
	<material name="white"/>
     </visual>
     <inertial>
	<mass value="1e-5" />
	<origin xyz="0 0 0" rpy="0 0 0"/>
	<inertia ixx="1e-6" ixy="0" ixz="0" iyy="1e-6" iyz="0" izz="1e-6" />
     </inertial> 
  </link>
 	 
  <joint name="hokuyo_joint" type="fixed">
  	<axis xyz="0 1 0" />
	<origin xyz="0.23 0 0.06" rpy="0 0 0"/>
	<parent link="link_chassis"/>
	<child link="hokuyo_link"/> 
  </joint>
  
  <link name="camera_link">
      <collision>
         <origin xyz="0 0 0" rpy="0 0 0"/>
	 <geometry>
	 <box size="0.05 0.05 0.05"/>
	 </geometry>
      </collision>
      <visual>
         <origin xyz="0 0 0" rpy="0 0 0"/>
	 <geometry>
	 <box size="0.05 0.05 0.05"/>
	 </geometry>
	 <material name="green" />
      </visual>
      <inertial>
         <mass value="1e-5" />
	 <origin xyz="0 0 0" rpy="0 0 0"/>
	 <inertia ixx="1e-6" ixy="0" ixz="0" iyy="1e-6" iyz="0" izz="1e-6" />
      </inertial>
  </link>
  
  <joint name="camera_joint" type="fixed">
	<axis xyz="0 1 0" />
	<origin xyz="0 0 0.525" rpy="0 0 0"/>
	<parent link="arm_link2"/>
	<child link="camera_link"/>
  </joint>
  
  <!-- Transission definition -->
  
  <transmission name="arm_base_joint_trans">
	<type>transmission_interface/SimpleTransmission</type>
	<joint name="arm_base_joint">
		<hardwareInterface>hardware_interface/EffortJointInterface</hardwareInterface>
	</joint>
	<actuator name="motor1">
		<hardwareInterface>hardware_interface/EffortJointInterface</hardwareInterface>
		<mechanicalInterface>1</mechanicalInterface>
	</actuator>
  </transmission>

  <transmission name="arm_joint1_trans">
	<type>transmission_interface/SimpleTransmission</type>
	<joint name="arm_joint1">
		<hardwareInterface>hardware_interface/EffortJointInterface</hardwareInterface>
	</joint>
	<actuator name="motor2">
		<hardwareInterface>hardware_interface/EffortJointInterface</hardwareInterface>
		<mechanicalInterface>1</mechanicalInterface>
	</actuator>
  </transmission>
   
  <transmission name="arm_joint2_trans">
	<type>transmission_interface/SimpleTransmission</type>
	<joint name="arm_joint2">
		<hardwareInterface>hardware_interface/EffortJointInterface</hardwareInterface>
	</joint>
	<actuator name="motor3">
		<hardwareInterface>hardware_interface/EffortJointInterface</hardwareInterface>
		<mechanicalInterface>1</mechanicalInterface>
	</actuator>
  </transmission> 

</robot>
